INFO - Log de condiciones convertidas a formato pandas
INFO - Inicio del proceso de validación de datos.
INFO - Se encontraron 892 condiciones.
ERROR - P02A01 = 2 y (P02A04A>0|P02A04B esta en (1,2,3,4,5,6,7,8,9,10,11,12,13,98): ('EOF in multi-line statement', (2, 0)). Error de nan
ERROR - Exception during reset or similar
Traceback (most recent call last):
  File "c:\Users\mchinchilla\AppData\Local\Programs\Python\Python311\Lib\site-packages\sqlalchemy\pool\base.py", line 988, in _finalize_fairy
    fairy._reset(
  File "c:\Users\mchinchilla\AppData\Local\Programs\Python\Python311\Lib\site-packages\sqlalchemy\pool\base.py", line 1436, in _reset
    pool._dialect.do_rollback(self)
  File "c:\Users\mchinchilla\AppData\Local\Programs\Python\Python311\Lib\site-packages\sqlalchemy\engine\default.py", line 691, in do_rollback
    dbapi_connection.rollback()
  File "c:\Users\mchinchilla\AppData\Local\Programs\Python\Python311\Lib\site-packages\mysql\connector\connection_cext.py", line 496, in rollback
    self._cmysql.rollback()
_mysql_connector.MySQLInterfaceError: Lost connection to MySQL server during query
ERROR - Exception during reset or similar
Traceback (most recent call last):
  File "c:\Users\mchinchilla\AppData\Local\Programs\Python\Python311\Lib\site-packages\sqlalchemy\pool\base.py", line 988, in _finalize_fairy
    fairy._reset(
  File "c:\Users\mchinchilla\AppData\Local\Programs\Python\Python311\Lib\site-packages\sqlalchemy\pool\base.py", line 1436, in _reset
    pool._dialect.do_rollback(self)
  File "c:\Users\mchinchilla\AppData\Local\Programs\Python\Python311\Lib\site-packages\sqlalchemy\engine\default.py", line 691, in do_rollback
    dbapi_connection.rollback()
  File "c:\Users\mchinchilla\AppData\Local\Programs\Python\Python311\Lib\site-packages\mysql\connector\connection_cext.py", line 496, in rollback
    self._cmysql.rollback()
_mysql_connector.MySQLInterfaceError: Lost connection to MySQL server during query
ERROR - PPA03  > 2 Y (P05A04 >=1 o P05A04<=10 o P05A04=98): Python keyword not valid identifier in numexpr query (<unknown>, line 1). Error de AS
ERROR - PPA03 <= 6 y(P05B05A = 2 y P05B05B no es vacío): Python keyword not valid identifier in numexpr query (<unknown>, line 1). Error de AS
